I'm sorry, but an uncaught exception occurred.

While running game code:
  File "game/script.rpy", line 344, in script
    $ renpy.call_in_new_context("open_document")
  File "game/script.rpy", line 344, in <module>
    $ renpy.call_in_new_context("open_document")
ScriptError: could not find label 'open_document'.

-- Full Traceback ------------------------------------------------------------

Full traceback:
  File "game/script.rpy", line 344, in script
    $ renpy.call_in_new_context("open_document")
  File "C:\Users\User\Desktop\Book\renpy-8.2.0-sdk\renpy\ast.py", line 823, in execute
    renpy.python.py_exec_bytecode(self.code.bytecode, self.hide, store=self.store)
  File "C:\Users\User\Desktop\Book\renpy-8.2.0-sdk\renpy\python.py", line 1178, in py_exec_bytecode
    exec(bytecode, globals, locals)
  File "game/script.rpy", line 344, in <module>
    $ renpy.call_in_new_context("open_document")
  File "C:\Users\User\Desktop\Book\renpy-8.2.0-sdk\renpy\game.py", line 358, in call_in_new_context
    return renpy.execution.run_context(False)
  File "C:\Users\User\Desktop\Book\renpy-8.2.0-sdk\renpy\execution.py", line 955, in run_context
    context.run()
  File "C:\Users\User\Desktop\Book\renpy-8.2.0-sdk\renpy\script.py", line 1103, in lookup
    raise ScriptError("could not find label '%s'." % str(original))
ScriptError: could not find label 'open_document'.

Windows-10-10.0.19045 AMD64
Ren'Py 8.2.0.24012702
Zero Keep Out 1.0
Tue May 21 23:44:14 2024
