I'm sorry, but an uncaught exception occurred.

While running game code:
  File "game/assets.rpy", line 83, in script
    image mother_kitchen_cook = Glitch(
  File "game/assets.rpy", line 83, in <module>
    image mother_kitchen_cook = Glitch(
  File "game/mini_games/glitchs_api.rpy", line 73, in __init__
    self.glitch_strength = glitch_strength
  File "game/mini_games/glitchs_api.rpy", line 124, in glitch_strength
    raise ValueError(__("Некорректное значение 'glitch_strength'"))
ValueError: Некорректное значение 'glitch_strength'

-- Full Traceback ------------------------------------------------------------

Full traceback:
  File "game/assets.rpy", line 83, in script
    image mother_kitchen_cook = Glitch(
  File "D:\Soft\RenPy\renpy-8.1.3-sdk\renpy\ast.py", line 1237, in execute
    img = renpy.python.py_eval_bytecode(self.code.bytecode)
  File "D:\Soft\RenPy\renpy-8.1.3-sdk\renpy\python.py", line 1146, in py_eval_bytecode
    return eval(bytecode, globals, locals)
  File "game/assets.rpy", line 83, in <module>
    image mother_kitchen_cook = Glitch(
  File "game/mini_games/glitchs_api.rpy", line 73, in __init__
    self.glitch_strength = glitch_strength
  File "D:\Soft\RenPy\renpy-8.1.3-sdk\renpy\revertable.py", line 97, in do_mutation
    return method(self, *args, **kwargs)
  File "game/mini_games/glitchs_api.rpy", line 124, in glitch_strength
    raise ValueError(__("Некорректное значение 'glitch_strength'"))
ValueError: Некорректное значение 'glitch_strength'

Windows-10-10.0.22631 AMD64
Ren'Py 8.1.3.23091805
Zero Keep Out 1.0
Sun May 26 23:51:41 2024
